Workbook

Sheet Summary
D3: Desk | E3: Office | F3: Corridor | G3: Column | H3: Storage | I3: Kitchen | J3: Outside | K3: Staircase | L3: Entrance | M3: Utility | N3: Techbar | O3: Entertainment | P3: Bathrooms | Q3: Canteen
C4: North | D4: =North!C2 -> 48 | E4: =North!D2 -> 14 | F4: =North!E2 -> 27 | G4: =North!F2 -> 8 | H4: =North!G2 -> 3 | I4: =North!H2 -> 0 | J4: =North!I2 -> 0 | K4: =North!J2 -> 0 | ... Q4: =North!P2 -> 0
C5: East | D5: =East!B2 -> 88 | E5: =East!C2 -> 6 | F5: =East!D2 -> 29 | G5: =East!E2 -> 23 | H5: =East!F2 -> 1 | I5: =East!G2 -> 1 | J5: =East!H2 -> 1 | K5: =East!I2 -> 4 | ... Q5: =East!O2 -> 0
C6: South | D6: =South!B2 -> 0 | E6: =South!C2 -> 6 | F6: =South!D2 -> 3 | G6: =South!E2 -> 9 | H6: =South!F2 -> 1 | I6: =South!G2 -> 1 | J6: =South!H2 -> 0 | K6: =South!I2 -> 0 | ... Q6: =South!O2 -> 0
C7: West | D7: =West!B2 -> 44 | E7: =West!C2 -> 23 | F7: =West!D2 -> 26 | G7: =West!E2 -> 23 | H7: =West!F2 -> 5 | I7: =West!G2 -> 1 | J7: =West!H2 -> 1 | K7: =West!I2 -> 3 | ... Q7: =West!O2 -> 1
C8: Total | D8: =SUM(D4:D7) -> 180 | E8: =SUM(E4:E7) -> 49 | F8: =SUM(F4:F7) -> 85 | G8: =SUM(G4:G7) -> 63 | H8: =SUM(H4:H7) -> 10 | I8: =SUM(I4:I7) -> 3 | J8: =SUM(J4:J7) -> 2 | K8: =SUM(K4:K7) -> 7 | ... Q8: =SUM(Q4:Q7) -> 1

Sheet North
C2: =COUNTA(C4:C51) -> 48 | D2: =COUNTA(D4:D50) -> 14 | E2: =COUNTA(E4:E50) -> 27 | F2: =COUNTA(F4:F50) -> 8 | G2: =COUNTA(G4:G50) -> 3 | H2: =COUNTA(H4:H50) -> 0 | I2: =COUNTA(I4:I50) -> 0 | J2: =COUNTA(J4:J50) -> 0 | K2: =COUNTA(K4:K50) -> 0 | ... P2: =COUNTA(P4:P50) -> 0
C3: Desk | D3: Office | E3: Corridor | F3: Column | G3: Storage | H3: Kitchen | I3: Outside | J3: Staircase | K3: Entrance | L3: Utility | M3: Techbar | N3: Entertainment | O3: Bathrooms | P3: Canteen
C4: 01N007 | D4: 01N001 | E4: C01034 | F4: Col#01N05 | G4: S01040 | L4: S01035
C5: 01N015 | D5: 01N002 | E5: C01037 | F5: Col#01N10 | G5: S01039 | L5: S01036
C6: 01N016 | D6: 01N003 | E6: C01038 | F6: Col#01N20 | G6: S01037 | L6: S01041
C7: 01N017 | D7: 01N004 | E7: C01039 | F7: Col#01N25 | L7: S01042
C8: 01N018 | D8: 01N005 | E8: C01040 | F8: Col#01N30 | L8: S01043
C9: 01N019 | D9: 01N006 | E9: C01041 | F9: Col#01N35 | L9: S01038
C10: 01N020 | D10: 01N027 | E10: C01042 | F10: Col#01N40 | L10: S01050
C11: 01N021 | D11: 01N028 | E11: C01043 | F11: Col#01N45
C12: 01N022 | D12: 01N029 | E12: C01044
C13: 01N023 | D13: 01N030 | E13: C01045
C14: 01N024 | D14: 01N092 | E14: C01046
C15: 01N025 | D15: 01N093 | E15: C01047
C16: 01N026 | D16: 01N100 | E16: C01048
C17: 01N040 | D17: 01N101 | E17: C01049
C18: 01N050 | E18: C01050
C19: 01N051 | E19: C01051
C20: 01N052 | E20: C01052
C21: 01N053 | E21: C01053
C22: 01N054 | E22: C01054
C23: 01N055 | E23: C01055
C24: 01N056 | E24: C01056
C25: 01N057 | E25: C01057
C26: 01N058 | E26: C01058
C27: 01N059 | E27: C01059
C28: 01N060 | E28: C01060
C29: 01N061 | E29: C01061
C30: 01N062 | E30: C01089
C31: 01N063
C32: 01N064
C33: 01N065
C34: 01N080
C35: 01N081
C36: 01N082
C37: 01N083
C38: 01N084
C39: 01N085
C40: 01N086
C41: 01N087
...

Sheet East
B2: =COUNTA(B4:B91) -> 88 | C2: =COUNTA(C4:C91) -> 6 | D2: =COUNTA(D4:D91) -> 29 | E2: =COUNTA(E4:E91) -> 23 | F2: =COUNTA(F4:F91) -> 1 | G2: =COUNTA(G4:G91) -> 1 | H2: =COUNTA(H4:H91) -> 1 | I2: =COUNTA(I4:I91) -> 4 | ... O2: =COUNTA(O4:O91) -> 0
B3: Desk | C3: Office | D3: Corridor | E3: Column | F3: Storage | G3: Kitchen | H3: Outside | I3: Staircase | J3: Entrance | K3: Utility | L3: Techbar | M3: Entertainment | N3: Bathrooms | O3: Canteen
B4: 01E001 | C4: 01E033 | D4: C01080 | E4: Col#01E105 | F4: S01046 | G4: 01E034 | H4: 01E036 | I4: V01000 | J4: S01047 | K4: 01E035 | N4: S01034
B5: 01E002 | C5: 01E037 | D5: C01035 | E5: Col#01E05 | I5: V01002 | K5: S01031 | N5: S01033
B6: 01E003 | C6: 01E038 | D6: C01036 | E6: Col#01E10 | I6: V01003 | N6: S01032
B7: 01E004 | C7: 01E092 | D7: C01062 | E7: Col#01E100 | I7: V01004
B8: 01E005 | C8: 01E093 | D8: C01063 | E8: Col#01E110
B9: 01E006 | C9: 01E094 | D9: C01064 | E9: Col#01E15
B10: 01E007 | D10: C01065 | E10: Col#01E20
B11: 01E008 | D11: C01066 | E11: Col#01E25
B12: 01E009 | D12: C01067 | E12: Col#01E30
B13: 01E010 | D13: C01068 | E13: Col#01E35
B14: 01E011 | D14: C01069 | E14: Col#01E40
B15: 01E012 | D15: C01070 | E15: Col#01E45
B16: 01E013 | D16: C01071 | E16: Col#01E50
B17: 01E014 | D17: C01072 | E17: Col#01E55
B18: 01E015 | D18: C01073 | E18: Col#01E60
B19: 01E016 | D19: C01074 | E19: Col#01E65
B20: 01E017 | D20: C01075 | E20: Col#01E70
B21: 01E018 | D21: C01076 | E21: Col#01E75
... B26: 01E023 | D26: C01082 | E26: Col#01N15
B27: 01E024 | D27: C01083
B28: 01E025 | D28: C01084
B29: 01E026 | D29: C01085
B30: 01E027 | D30: C01086
B31: 01E028 | D31: C01087
B32: 01E029 | D32: C01088
B33: 01E030
B34: 01E031
B35: 01E048
B36: 01E049
B37: 01E050
B38: 01E051
B39: 01E052
B40: 01E053
B41: 01E054
B42: 01E055
B43: 01E056
B44: 01E057
... B91: 01E112

Sheet South
B2: =COUNTA(B4:B100) -> 0 | C2: =COUNTA(C4:C100) -> 6 | D2: =COUNTA(D4:D100) -> 3 | E2: =COUNTA(E4:E100) -> 9 | F2: =COUNTA(F4:F100) -> 1 | G2: =COUNTA(G4:G100) -> 1 | H2: =COUNTA(H4:H100) -> 0 | I2: =COUNTA(I4:I100) -> 0 | ... O2: =COUNTA(O4:O100) -> 0
B3: Desk | C3: Office | D3: Corridor | E3: Column | F3: Storage | G3: Kitchen | H3: Outside | I3: Staircase | J3: Entrance | K3: Utility | L3: Techbar | M3: Entertainment | N3: Bathrooms | O3: Canteen
C4: 01S002 | D4: C01031 | E4: Col#01S05 | F4: S01045 | G4: S01044 | J4: S01028 | K4: S01029 | L4: 01S005 | M4: 01S001
C5: 01S003 | D5: C01032 | E5: Col#01S20 | K5: S01030 | L5: 01S007
C6: 01S004 | D6: C01033 | E6: Col#01S25
C7: 01S009 | E7: Col#01S40
C8: 01S010 | E8: Col#01S30
C9: 01S006 | E9: Col#01S10
E10: Col#01S15
E11: Col#01S45
E12: Col#01S35

Sheet West
B2: =COUNTA(B4:B47) -> 44 | C2: =COUNTA(C4:C47) -> 23 | D2: =COUNTA(D4:D47) -> 26 | E2: =COUNTA(E4:E47) -> 23 | F2: =COUNTA(F4:F47) -> 5 | G2: =COUNTA(G4:G47) -> 1 | H2: =COUNTA(H4:H47) -> 1 | I2: =COUNTA(I4:I47) -> 3 | ... O2: =COUNTA(O4:O47) -> 1
B3: Desk | C3: Office | D3: Corridor | E3: Column | F3: Storage | G3: Kitchen | H3: Outside | I3: Staircase | J3: Entrance | K3: Utility | L3: Techbar | M3: Entertainment | N3: Bathrooms | O3: Canteen
B4: 01W060 | C4: 01W010 | D4: C01012 | E4: Col#01W05 | F4: S01002 | G4: S01013 | H4: S01051 | I4: V01001 | J4: S01015 | K4: S01001 | M4: 01W008 | N4: S01003 | O4: S01014
B5: 01W065 | C5: 01W020 | D5: 01C008 | E5: Col#01W10 | F5: S01017 | I5: V01005 | K5: S01005 | M5: 01W009 | N5: S01004
B6: 01W070 | C6: 01W055 | D6: C01005 | E6: Col#01W100 | F6: S01018 | I6: V01006 | K6: S01008 | M6: 01W108 | N6: S01006
B7: 01W071 | C7: 01W056 | D7: C01006 | E7: Col#01W105 | F7: S01019 | K7: S01009 | N7: S01007
B8: 01W072 | C8: 01W057 | D8: C01007 | E8: Col#01W110 | F8: S01020 | K8: S01010 | N8: S01011
B9: 01W073 | C9: 01W058 | D9: C01009 | E9: Col#01W115 | K9: S01016 | N9: S01012
B10: 01W074 | C10: 01W059 | D10: C01010 | E10: Col#01W15 | K10: S01023 | N10: S01021
B11: 01W075 | C11: 01W061 | D11: C01011 | E11: Col#01W20 | K11: S01026 | N11: S01022
B12: 01W076 | C12: 01W062 | D12: C01013 | E12: Col#01W25 | N12: S01024
B13: 01W077 | C13: 01W063 | D13: C01014 | E13: Col#01W30 | N13: S01025
B14: 01W078 | C14: 01W064 | D14: C01015 | E14: Col#01W35 | N14: S01027
B15: 01W080 | C15: 01W067 | D15: C01016 | E15: Col#01W40 | N15: S01048
B16: 01W081 | C16: 01W068 | D16: C01017 | E16: Col#01W45 | N16: S01049
B17: 01W082 | C17: 01W095 | D17: C01018 | E17: Col#01W50
B18: 01W083 | C18: 01W096 | D18: C01019 | E18: Col#01W55
B19: 01W084 | C19: 01W097 | D19: C01020 | E19: Col#01W60
B20: 01W085 | C20: 01W098 | D20: C01021 | E20: Col#01W65
B21: 01W090 | C21: 01W099 | D21: C01022 | E21: Col#01W70
B22: 01W091 | C22: 01W103 | D22: C01023 | E22: Col#01W75
B23: 01W092 | C23: 01W104 | D23: C01024 | E23: Col#01W80
B24: 01W093 | C24: 01W105 | D24: C01025 | E24: Col#01W85
B25: 01W094 | C25: 01W106 | D25: C01026 | E25: Col#01W90
B26: 01W100 | C26: 01W107 | D26: C01027 | E26: Col#01W95
B27: 01W101 | D27: C01028
B28: 01W102 | D28: C01029
B29: 01W109 | D29: C01030
B30: 01W115
B31: 01W116
B32: 01W117
B33: 01W118
B34: 01W119
B35: 01W120
B36: 01W121
B37: 01W122
B38: 01W123
B39: 01W124
B40: 01W125
B41: 01W126
...
